Workbook

Sheet MT
A1: ID Regolam. Esercizio | B1: Impianto primario alimentante (in assetto standard) | G1: Caratteristiche Tecniche Punto di Interconnessione MT | AB1: Esercente responsabile delle informazioni sulle Interruzioni (2) | AC1: Caratteristiche del Punto di Misura | AH1: Note generali | AI1: Telecontrollo (SI, Telecontrollabile, NO) | AJ1: Estensione NODO E-D | AK1: Estensione NODO Duereti | AL1: Note
G2: NODO di competenza e-distribuzione | K2: Ubicazione del punto di confine | S2: Nodo di competenza Duereti | X2: da e-distribuzione a Duereti | Z2: da Duereti a e-distribuzione
B3: Proprietà Cabina Primaria | C3: Cabina Primaria | D3: N° linea | E3: Nome Linea | F3: Stato del neutro | G3: Codice nodo | H3: Denominazione del nodo | I3: Indirizzo | J3: Comune | K3: Ubicazione | L3: Coordinate punto di confine (ove rilevante) | M3: Indirizzo | N3: Comune | O3: Competenza ramo MT di confine | P3: Assetto standard | Q3: Mappa | R3: Schematizzazione | S3: Codice nodo | T3: Denominazione del nodo | U3: Indirizzo | V3: Comune | W3: Stato interconnessione | X3: tipo di alimentazione | Y3: potenza disponibile kW | Z3: tipo di alimentazione | AA3: potenza disponibile kW | AB3: e-distribuzione / Duereti | AC3: POD Duereti | AD3: POD ED | AE3: Ubicazione | AF3: Proprietà misuratore | AG3: Proprietà Riduttori
A4: 1 | B4: Duereti | C4: ARESE | D4: DU1039379 | E4: =VLOOKUP(D4,Foglio1!A1:B4126,2,FALSE) -> BARIANA | G4: DU30-2-556057 | H4: MEC.DEL.NORD | I4: VIA PONCHIELLI, 227 | J4: Caronno Pertusella | K4: DU30-2-556057 | L4: 45.581924 - 9.057621 | M4: VIA PONCHIELLI, 227 | N4: Caronno Pertusella | O4: Duereti terminali compresi | P4: APERTO | S4: DU10-2-481887 | T4: CADORE | U4: V.ORTOLANI DF 32 | V4: Garbagnate Milanese | W4: Definitivo | X4: S | Y4: 1600 | Z4: S | AA4: 2200 | AD4: IT001E120945327 | AE4: DU30-2-556057 | AF4: E-D | AG4: E-D | AI4: Telecontrollabile
A5: 2 | B5: Duereti | C5: ARESE | D5: DU1039379 | E5: =VLOOKUP(D5,Foglio1!A2:B4127,2,FALSE) -> BARIANA | G5: DU30-2-227568 | H5: MAYER | I5: Via V Giornate, 2045 | J5: Caronno Pertusella | K5: DU30-2-227568 | L5: 45.581933 - 9.060178 | M5: Via V Giornate, 2045 | N5: Caronno Pertusella | O5: Duereti terminali compresi | P5: APERTO | S5: DU10-3-268403 | T5: PALO DI DERIV | U5: 45,580271 - 9,061776 | V5: Garbagnate Milanese | W5: Definitivo | X5: S | Y5: 1300 | Z5: S | AA5: 1300 | AD5: IT001E124230934 | AE5: DU30-2-227568 | AF5: E-D | AG5: E-D | AI5: SI
A6: 3 | B6: Duereti | C6: ARESE | D6: DU1012584 | E6: =VLOOKUP(D6,Foglio1!A3:B4128,2,FALSE) -> BAR.EST | G6: DU30-2-556057 | H6: MEC.DEL.NORD | I6: VIA PONCHIELLI, 227 | J6: Caronno Pertusella | K6: DU30-2-556057 | L6: 45.581924 - 9.057621 | M6: VIA PONCHIELLI, 227 | N6: Caronno Pertusella | O6: Duereti terminali compresi | P6: CHIUSO | S6: DU00-1-383645 | T6: CP ARESE | U6: VIA CESARE BATTISTI 95 | V6: Arese | W6: Definitivo | Z6: P | AA6: 2500 | AD6: IT001E120945602 | AE6: DU30-2-556057 | AF6: E-D | AG6: E-D | AI6: Telecontrollabile
A7: 4 | B7: e-distribuzione | C7: OSPIATE_1523 | D7: DU1043110 | E7: MAZZINO | G7: DU00-1-380915 | H7: CP OSPIATE | I7: VIA MARCONI-FR. OSPIATE | J7: Bollate-Cascina Nuova | K7: DU10-2-254712 | L7: 45.536019 - 9.075801 | M7: V.OSPIATE, 51 MAZZO DI RHO | N7: Rho | O7: E-DISTRIBUZIONE terminali compresi | P7: CHIUSO | S7: DU10-2-254712 | T7: DRIVER HARRIS | U7: V.OSPIATE, 51 FRAZ. MAZZO DI RHO | V7: Rho | W7: Definitivo | X7: P | Y7: 1000 | AD7: IT001E121237393 | AE7: DU10-2-254712 | AF7: Duereti | AG7: Duereti | AI7: Telecontrollabile
A8: 5 | B8: Duereti | C8: VERNATE | D8: DU1017264 | E8: =VLOOKUP(D8,Foglio1!A5:B4130,2,FALSE) -> MORIVIONE | G8: DU10-2-121316 | H8: CAIELLA | I8: STR.CASORATE-MOTTA | J8: Casorate Primo | K8: DU10-2-203935 | L8: 45.290599 - 9.008474 | M8: C.SPAGNOLA | N8: Motta Visconti | O8: E-DISTRIBUZIONE fino agli amarri (calate escluse) | P8: CHIUSO | S8: DU10-2-203935 | T8: C.SPAGNOLA | U8: C.SPAGNOLA | V8: Motta Visconti | W8: Definitivo | Z8: P | AA8: 100 | AD8: IT001E121114178 | AE8: DU10-2-203935 | AF8: Duereti | AG8: Duereti | AI8: SI
A9: 6 | B9: Duereti | C9: VERNATE | D9: DU1017264 | E9: =VLOOKUP(D9,Foglio1!A6:B4131,2,FALSE) -> MORIVIONE | G9: DU10-3-264468 | H9: SEZ A PALO | I9: 45,296198 - 9,02995 | J9: Trovo | K9: DU10-2-426331 | L9: 45.297164 - 9.029487 | M9: C.MORIVIONE | N9: Vernate | O9: E-DISTRIBUZIONE terminali compresi | P9: APERTO | S9: DU10-2-426331 | T9: MORIVIONE | U9: C.MORIVIONE | V9: Vernate | W9: Definitivo | X9: S | Y9: 1800 | Z9: S | AA9: 1600 | AD9: IT001E124332184 | AE9: DU10-2-426331 | AF9: Duereti | AG9: Duereti | AI9: SI
A10: 7 | B10: Duereti | C10: VERNATE | D10: DU1048300 | E10: =VLOOKUP(D10,Foglio1!A7:B4132,2,FALSE) -> NOVIGLIO | G10: DU10-2-744382 | H10: COLORTEX | I10: VIA ORLANDI | J10: Casorate Primo | K10: DU10-2-629371 | L10: 45.325318 - 9.012906 | M10: VIA MARIO GIULIANI 9 | N10: Bubbiano | O10: E-DISTRIBUZIONE terminali compresi | P10: CHIUSO | S10: DU10-2-629371 | T10: LOT.ESTOV | U10: VIA MARIO GIULIANI 9 | V10: Bubbiano | W10: Definitivo | Z10: P | AA10: 1000 | AD10: IT001E121114348 | AE10: DU10-2-629371 | AF10: Duereti | AG10: Duereti | AI10: SI
A11: 8 | B11: Duereti | C11: ARESE | D11: DU1042581 | E11: =VLOOKUP(D11,Foglio1!A8:B4133,2,FALSE) -> VILLORESI | G11: DU10-2-508435 | H11: DRAGA LATERI | I11: V.MADONNA FAMETTA, 26 | J11: Bollate-Ospiate | K11: DU10-2-508435 | L11: 45.56473 - 9.096001 | M11: V.MADONNA FAMETTA, 26 | N11: Bollate-Ospiate | O11: Duereti terminali compresi | P11: APERTO | S11: DU10-3-256982 | T11: SEZ. A PALO | U11: Ciclopedonale Expo 2015 snc | V11: Garbagnate Milanese | W11: Definitivo | X11: S | Y11: 1300 | Z11: S | AA11: 1300 | AD11: IT001E121114569 | AE11: DU10-2-508435 | AF11: E-D | AG11: E-D | AI11: SI
A12: 9 | B12: Duereti | C12: ARESE | D12: DU1049678 | E12: =VLOOKUP(D12,Foglio1!A9:B4134,2,FALSE) -> DEPURATORE | G12: DU30-2-227568 | H12: MAYER | I12: Via V Giornate, 2045 | J12: Caronno Pertusella | K12: DU10-2-384947 | L12: 45.579336 - 9.059088 | M12: Via Trattati di Roma | N12: Garbagnate Milanese | O12: E-DISTRIBUZIONE terminali compresi | P12: CHIUSO | S12: DU10-2-384947 | T12: C-PETROL | U12: Via Trattati di Roma | V12: Garbagnate Milanese | W12: Definitivo | Z12: P | AA12: 3200 | AD12: IT001E120934732 | AE12: DU10-2-384947 | AF12: Duereti | AG12: Duereti | AI12: SI
A13: 10 | B13: e-distribuzione | C13: BUSTO SUD | D13: DU1015810 | E13: MADDALENA EDM | G13: DU30-2-593041 | H13: ACCAM | I13: VIA ARCONATE | J13: Busto A.Sud | K13: DU30-2-593041 | L13: 45.573027 - 8.838395 | M13: VIA ARCONATE | N13: Busto A.Sud | O13: Duereti terminali compresi | P13: CHIUSO | S13: DU10-2-403127 | T13: BARGA | U13: VIA BRUGHIERE | V13: Magnago | W13: Definitivo | Z13: P | AA13: 3000 | AD13: IT001E120977709 | AE13: DU30-2-593041 | AF13: E-D | AG13: E-D | AI13: Telecontrollabile
A14: 11 | B14: e-distribuzione | C14: BUSTO SUD | D14: DU1015810 | E14: MADDALENA EDM | G14: DU30-2-593041 | H14: ACCAM | I14: VIA ARCONATE | J14: Busto A.Sud | K14: DU30-2-593041 | L14: 45.573027 - 8.838395 | M14: VIA ARCONATE | N14: Busto A.Sud | O14: Duereti terminali compresi | P14: CHIUSO | S14: DU10-3-242615 | T14: SEZ.A PALO | U14: 45,568997-8,836534 | V14: Legnano | W14: Definitivo | X14: P | Y14: 1200 | AD14: IT001E120977776 | AE14: DU30-2-593041 | AF14: E-D | AG14: E-D | AI14: Telecontrollabile
A15: 12 | B15: e-distribuzione | C15: BUSTO SUD | D15: DU1015810 | E15: MADDALENA EDM | G15: DU30-2-411056 | H15: IMP.DEPURAZ. | I15: VIA TRAVERSAGNA (INGR. VIA ARCONATE) | J15: Busto A.Sud | K15: DU30-2-411056 | L15: 45.56988 - 8.838932 | M15: VIA TRAVERSAGNA (INGR. VIA ARCONATE) | N15: Busto A.Sud | O15: Duereti terminali compresi | P15: CHIUSO | S15: DU10-3-202729 | T15: SEZ.A PALO | U15: 45,567197-8,836395 | V15: Legnano | W15: Definitivo | X15: P | Y15: 1000 | AD15: IT001E120945912 | AE15: DU30-2-411056 | AF15: E-D | AG15: E-D | AI15: Telecontrollabile
A16: 13 | B16: Duereti | C16: ARESE | D16: DU1040398 | E16: =VLOOKUP(D16,Foglio1!A13:B4138,2,FALSE) -> BAR.OVEST | G16: DU30-2-352871 | H16: CAFFIN. LALAC | I16: Via Rossini, 340 | J16: Caronno Pertusella | K16: DU10-2-335666 | L16: 45.580062 - 9.044969 | M16: V.VERGA, 32A | N16: Lainate | O16: E-DISTRIBUZIONE terminali compresi | P16: APERTO | S16: DU10-2-335666 | T16: OCCHIPINTI | U16: V.VERGA, 32A | V16: Lainate | W16: Definitivo | X16: S | Y16: 1500 | Z16: S | AA16: 2000 | AD16: IT001E121114780 | AE16: DU10-2-335666 | AF16: Duereti | AG16: Duereti | AI16: Telecontrollabile
A17: 14 | B17: e-distribuzione | C17: BUSTO SUD | D17: DU1015810 | E17: MADDALENA EDM | G17: DU00-1-385755 | H17: CP BUSTO SUD | I17: V.LE DELLE INDUSTRIE | J17: Busto Arsizio | K17: DU10-2-454479 | L17: 45.578489 - 8.833368 | M17: V.BRUGHIERE | N17: Magnago | O17: E-DISTRIBUZIONE terminali compresi | P17: CHIUSO | S17: DU10-2-454479 | T17: BIMA | U17: V.BRUGHIERE | V17: Magnago | W17: Definitivo | X17: P | Y17: 3500 | AD17: IT001E121237407 | AE17: DU10-2-454479 | AF17: Duereti | AG17: Duereti | AI17: Telecontrollabile
A18: 15 | B18: e-distribuzione | C18: BUSTO SUD | D18: DU1018080 | E18: BIENAT EDM | G18: DU00-1-385755 | H18: CP BUSTO SUD | I18: V.LE DELLE INDUSTRIE | J18: Busto Arsizio | K18: DU10-2-168174 | L18: 45.579612 - 8.832836 | M18: V.SARDEGNA | N18: Magnago | O18: E-DISTRIBUZIONE terminali compresi | P18: CHIUSO | S18: DU10-2-168174 | T18: CHIERICHETTI | U18: V.SARDEGNA | V18: Magnago | W18: Definitivo | X18: P | Y18: 3000 | AD18: IT001E124330572 | AE18: DU10-2-168174 | AF18: Duereti | AG18: Duereti | AI18: Telecontrollabile
A19: 16 | B19: e-distribuzione | C19: BUSTO SUD | D19: DU1024562 | E19: VANZAG EDM | G19: DU00-1-385755 | H19: CP BUSTO SUD | I19: V.LE DELLE INDUSTRIE | J19: Busto Arsizio | K19: DU10-2-516239 | L19: 45.581499 - 8.814337 | M19: Via Pascoli 5 | N19: Magnago | O19: E-DISTRIBUZIONE fino ai terminali compresi | P19: CHIUSO | S19: DU10-2-516239 | T19: PASCOLI | U19: Via Pascoli 5 | V19: Magnago | W19: Definitivo | X19: P | Y19: 2500 | AD19: IT001E121237415 | AE19: DU10-2-516239 | AF19: Duereti | AG19: Duereti | AI19: SI
A20: 17 | B20: e-distribuzione | C20: BUSTO SUD | D20: DU1024562 | E20: VANZAG EDM | G20: DU30-2-386084 | H20: F.N.M | I20: SCAMBIO CONF. MAGNAGO | J20: Busto Arsizio | K20: DU30-2-386084 | L20: 45.598702 - 8.811966 | M20: SCAMBIO CONF. MAGNAGO | N20: Busto Arsizio | O20: Duereti terminali compresi | P20: CHIUSO | S20: DU10-2-505881 | T20: BORLANDELLI | U20: Via Per Lonate | V20: Magnago | W20: Definitivo | Z20: P | AA20: 160 | AD20: IT001E124230438 | AE20: DU30-2-386084 | AF20: E-D | AG20: E-D | AI20: SI
A21: 18 | B21: e-distribuzione | C21: BUSTO SUD | D21: DU1024562 | E21: VANZAG EDM | G21: DU30-2-386084 | H21: F.N.M | I21: SCAMBIO CONF. MAGNAGO | J21: Busto Arsizio | K21: DU30-2-386084 | L21: 45.598702 - 8.811966 | M21: SCAMBIO CONF. MAGNAGO | N21: Busto Arsizio | O21: Duereti terminali compresi | P21: CHIUSO | S21: DU10-2-463844 | T21: ACQUATERM 2 | U21: Via Calvi | V21: Magnago | W21: Definitivo | AD21: IT001E124230543 | AE21: DU30-2-386084 | AF21: E-D | AG21: E-D | AI21: SI
A22: 19 | B22: Duereti | C22: BUSTOGAROLFO | D22: DU1048138 | E22: =VLOOKUP(D22,Foglio1!A19:B4144,2,FALSE) -> LUINI | G22: DU30-2-520847 | H22: SERVICE | I22: VIA NOVARA | J22: Busto A.Sud | K22: DU30-2-520847 | L22: 45.581547 - 8.873054 | M22: Via Novara | N22: Busto A.Sud | O22: Duereti terminali compresi | P22: CHIUSO | S22: DU10-3-206670 | T22: SEZ.A PALO | U22: 45,581735 ; 8,874189 | V22: Legnano | W22: Definitivo | Z22: P | AA22: 250 | AD22: IT001E120946463 | AE22: Rete BT CS 520847 | AF22: E-D | AG22: E-D | AI22: NO
A23: 20 | B23: Duereti | C23: BUSTOGAROLFO | D23: DU1048138 | E23: =VLOOKUP(D23,Foglio1!A20:B4145,2,FALSE) -> LUINI | G23: DU30-2-520847 | H23: SERVICE | I23: VIA NOVARA | J23: Busto A.Sud | K23: DU30-2-520847 | L23: 45.581547 - 8.873054 | M23: Via Novara | N23: Busto A.Sud | O23: Duereti terminali compresi | P23: CHIUSO | S23: DU10-2-409470 | T23: AMGA | U23: V.NOVARA, 250 | V23: Legnano | W23: Definitivo | AD23: IT001E120946463 | AE23: Rete BT CS 520847 | AF23: E-D | AG23: E-D | AI23: NO
A24: 21 | B24: e-distribuzione | C24: BUSTO SUD | D24: DU1045607 | E24: SICILI EDM | G24: DU00-1-385755 | H24: CP BUSTO SUD | I24: V.LE DELLE INDUSTRIE | J24: Busto Arsizio | K24: DU10-2-383537 | L24: 45.578718 - 8.834547 | M24: VIA BRUGHIERE 4 | N24: Magnago | O24: E-DISTRIBUZIONE terminali compresi | P24: CHIUSO | S24: DU10-2-383537 | T24: CARNE | U24: VIA BRUGHIERE 4 | V24: Magnago | W24: Definitivo | X24: P | Y24: 4500 | AD24: IT001E120905635 | AE24: DU10-2-383537 | AF24: Duereti | AG24: Duereti | AI24: Telecontrollabile
A25: 22 | B25: e-distribuzione | C25: BUSTO SUD | D25: DU1013711 | E25: TOSCANA | G25: DU30-4-228031 | H25: NODO RIGIDO | I25: VIA TRAVERSAGNA (LAT. VIA DAIRAGO) | J25: Busto A.Sud | K25: DU10-3-180129 | L25: 45.570977 - 8.857478 | M25: V.CAVOUR | N25: Dairago | O25: E-DISTRIBUZIONE fino ai codoli del sezionatore escluso | P25: APERTO | S25: DU10-3-180129 | T25: SEZ.A PALO | U25: 45,570977 - 8,857478 | V25: Dairago | W25: Definitivo | X25: S | Y25: 2300 | Z25: S | AA25: 2200 | AD25: IT001E121237431 | AE25: DU10-2-447444 | AF25: Duereti | AG25: Duereti | AI25: Telecontrollabile | AJ25: DU30.3.268165 - DU30.3.104698 | AL25: Estensione nodo Ed DU30.3.268165 è il codice del sezionatore del PTP
A26: 23 | B26: e-distribuzione | C26: CARONNO | D26: DU1034776 | E26: PRISCO | G26: DU00-1-384655 | H26: CP CARONNO | I26: VIA PER ASIAGO | J26: Caronno Pertusella | K26: DU10-2-269387 | L26: 45.582360 - 9.019497 | M26: CORSO EUROPA | N26: Lainate | O26: E-DISTRIBUZIONE terminali compresi | P26: CHIUSO | S26: DU10-2-269387 | T26: PRISCO | U26: CORSO EUROPA | V26: Lainate | W26: Definitivo | X26: P | Y26: 5300 | AD26: IT001E120934252 | AE26: DU10-2-269387 | AF26: Duereti | AG26: Duereti | AI26: SI
A27: 24 | B27: e-distribuzione | C27: UBOLDO | D27: DU1017984 | E27: CAPPELLETTA | G27: DU30-2-108846 | H27: MULLER | I27: Via Italia (confine Lainate) | J27: Origgio | K27: DU10-2-581121 | L27: 45.581481 - 9.014660 | M27: V. BERNINI, 2 | N27: Lainate | O27: E-DISTRIBUZIONE terminali compresi | P27: APERTO | S27: DU10-2-581121 | T27: VIA BERNINI | U27: V. BERNINI, 2 | V27: Lainate | W27: Definitivo | X27: S | Y27: 1500 | Z27: S | AA27: 1000 | AD27: IT001E124331714 | AE27: DU10-2-581121 | AF27: Duereti | AG27: Duereti | AI27: SI
A28: 25 | B28: e-distribuzione | C28: CARONNO | D28: DU1049431 | E28: CATTANEO | G28: DU30-2-230259 | H28: COBRA | I28: VIA SARONNINO | J28: Origgio | K28: DU10-2-426770 | L28: 45.581681 - 9.025061 | M28: V.UMBERTO I, 119 | N28: Lainate | O28: E-DISTRIBUZIONE terminali compresi | P28: CHIUSO | S28: DU10-2-426770 | T28: ORIGGIO | U28: V.UMBERTO I, 119 | V28: Lainate | W28: Definitivo | X28: P | Y28: 3000 | AD28: IT001E120934198 | AE28: DU10-2-426770 | AF28: Duereti | AG28: Duereti | AI28: Telecontrollabile
A29: 26 | B29: Duereti | C29: CERRO MAG. | D29: DU1029865 | E29: =VLOOKUP(D29,Foglio1!A26:B4151,2,FALSE) -> CASCINE | G29: DU30-4-248481 | H29: NODO RIGIDO | I29: 45,600264 - 8,97287 | J29: Uboldo | K29: DU10-3-228789 | L29: 45.600248 - 8.972865 | M29: VIA CERRO | N29: Uboldo | O29: 1) Duereti: ramo MT tra il sezionatore 228789 compreso e il 518212 2) E-distribuzione: ramo MT (Calate) tra il sezionatore 228789 escluso verso Nodo Rigido 248481. I due nodi citati sono su stesso palo. | P29: APERTO | S29: DU10-2-518212 | T29: INDUSTR.1 | U29: VIA 11 SETTEMBRE | V29: Cerro Maggiore | W29: Definitivo | X29: S | Y29: 2600 | Z29: S | AA29: 1500 | AD29: IT001E120931881 | AE29: DU10-2-518212 | AF29: Duereti | AG29: Duereti | AI29: Telecontrollabile | AJ29: DU30.2.583702 - DU30.2.516471
A30: 27 | B30: e-distribuzione | C30: CAPONAGO | D30: DU1039824 | E30: 7BUSSERO | G30: DU10-2-565145 | H30: CR-C.NA VALERA | I30: Via della Valera | J30: Carugate | K30: DU10-2-565145 | L30: 45.548803 - 9.357145 | M30: Via della Valera | N30: Carugate | O30: Duereti terminali compresi | P30: CHIUSO | S30: DU10-3-241640 | T30: SEZ.A PALO | U30: Via Valera | V30: Carugate | W30: Definitivo | Z30: P | AA30: 3000 | AD30: IT001E121069954 | AE30: DU10-2-565145 | AF30: E-D | AG30: E-D | AI30: Telecontrollabile
A31: 28 | B31: Duereti | C31: LEGNANO | D31: DU1011995 | E31: =VLOOKUP(D31,Foglio1!A28:B4153,2,FALSE) -> S.ERASMO | G31: DU30-2-310153 | H31: STANDA | I31: Via Diaz, 7 | J31: Castellanza | K31: DU10-2-583520 | L31: 45.605862 - 8.902298 | M31: V.PER BUSTO ARSIZIO, 15 | N31: Legnano | O31: E-DISTRIBUZIONE terminali compresi | P31: APERTO | S31: DU10-2-583520 | T31: CANALE 3 | U31: V.PER BUSTO ARSIZIO, 15 | V31: Legnano | W31: Definitivo | X31: S | Y31: 3000 | Z31: S | AA31: 1800 | AD31: IT001E120930991 | AE31: DU10-2-583520 | AF31: Duereti | AG31: Duereti | AI31: SI
A32: 29 | B32: Duereti | C32: LEGNANO | D32: DU1011995 | E32: =VLOOKUP(D32,Foglio1!A29:B4154,2,FALSE) -> S.ERASMO | G32: DU30-2-178901 | H32: CS VIA BINDA | I32: Via Binda, 21 | J32: Castellanza | K32: DU10-2-110178 | L32: 45.606847 - 8.905683 | M32: Via per Castellanza | N32: Legnano | O32: E-DISTRIBUZIONE terminali compresi | P32: APERTO | S32: DU10-2-110178 | T32: LEONIDA'S | U32: Via per Castellanza | V32: Legnano | W32: Definitivo | X32: S | Y32: 2600 | Z32: S | AA32: 1400 | AD32: IT001E120931741 | AE32: DU10-2-110178 | AF32: Duereti | AG32: Duereti | AI32: Telecontrollabile
A33: 30 | B33: e-distribuzione | C33: CAPONAGO | D33: DU1039824 | E33: 7BUSSERO | G33: DU10-3-260825 | H33: SEZ.A PALO | I33: 45,559848 - 9,379916 | J33: Caponago | K33: DU10-3-209776 | L33: 45.555503 - 9.378392 | N33: Pessano Con Bornago | O33: E-DISTRIBUZIONE fino ai codoli del sezionatore escluso | P33: CHIUSO | S33: DU10-3-209776 | T33: SEZ. A PALO | U33: 45,555503 - 9,378392 | V33: Pessano Con Bornago | W33: Definitivo | X33: P | Y33: 4400 | AD33: IT001E120978187 | AE33: DU10-2-592653 | AF33: E-D | AG33: E-D | AI33: Telecontrollabile
A34: 31 | B34: Duereti | C34: LEGNANO | D34: DU1020191 | E34: =VLOOKUP(D34,Foglio1!A31:B4156,2,FALSE) -> S.AMBROGIO | G34: DU30-2-605630 | H34: PAL.COMUNALE | I34: VIA VITTORIO VENETO | J34: Castellanza | K34: DU10-2-222396 | L34: 45.606882 - 8.904779 | M34: V.XXIX MAGGIO, 229 | N34: Legnano | O34: E-DISTRIBUZIONE terminali compresi | P34: APERTO | S34: DU10-2-222396 | T34: POGGIO | U34: V.XXIV MAGGIO, 229 | V34: Legnano | W34: Definitivo | X34: S | Y34: 2600 | Z34: S | AA34: 1500 | AD34: IT001E121237440 | AE34: DU10-2-222396 | AF34: Duereti | AG34: Duereti | AI34: SI
A35: 32 | B35: Duereti | C35: LEGNANO | D35: DU1029721 | E35: =VLOOKUP(D35,Foglio1!A32:B4157,2,FALSE) -> MAZZAFAME | G35: DU30-2-125069 | H35: SILPLA | I35: V.LE BORRI, 6 | J35: Castellanza | K35: DU10-2-353562 | L35: 45.601036 - 8.887666 | M35: V.EDISON, 7 | N35: Legnano | O35: E-DISTRIBUZIONE terminali compresi | P35: APERTO | S35: DU10-2-353562 | T35: BETA | U35: V.EDISON, 7 | V35: Legnano | W35: Definitivo | X35: S | Y35: 2000 | Z35: S | AA35: 2500 | AD35: IT001E120930621 | AE35: DU10-2-353562 | AF35: Duereti | AG35: Duereti | AI35: SI
A36: 33 | B36: Duereti | C36: LEGNANO | D36: DU1044964 | E36: =VLOOKUP(D36,Foglio1!A33:B4158,2,FALSE) -> FIRENZE | G36: DU30-2-242411 | H36: IMM.SATURNIA | I36: VIA ROSSELLI, 17 | J36: Castellanza | K36: DU10-2-289555 | L36: 45.601661 - 8.894979 | M36: V.ROBINO, 115 | N36: Legnano | O36: E-DISTRIBUZIONE terminali compresi | P36: APERTO | S36: DU10-2-289555 | T36: ALVIT | U36: V.ROBINO, 115 | V36: Legnano | W36: Definitivo | X36: S | Y36: 2000 | Z36: S | AA36: 2000 | AD36: IT001E121237458 | AE36: DU10-2-289555 | AF36: Duereti | AG36: Duereti | AI36: SI
A37: 34 | B37: Duereti | C37: LEGNANO | D37: DU1044964 | E37: =VLOOKUP(D37,Foglio1!A34:B4159,2,FALSE) -> FIRENZE | G37: DU30-2-361861 | H37: TIBA | I37: VIA JUCKER, 9/11 | J37: Castellanza | K37: DU10-2-289555 | L37: 45.601661 - 8.894979 | M37: V.ROBINO, 115 | N37: Legnano | O37: E-DISTRIBUZIONE terminali compresi | P37: APERTO | S37: DU10-2-289555 | T37: ALVIT | U37: V.ROBINO, 115 | V37: Legnano | W37: Definitivo | AD37: IT001E121237466 | AE37: DU10-2-289555 | AF37: Duereti | AG37: Duereti | AI37: SI
A38: 35 | B38: Duereti | C38: CASTANO P. | D38: DU1021541 | E38: =VLOOKUP(D38,Foglio1!A35:B4160,2,FALSE) -> MALPAGA | G38: DU30-2-524956 | H38: TINELLA | I38: VIA TURBIGACCIO, SN | J38: Lonate Pozzolo | K38: DU30-2-524956 | L38: 45.565056 - 8.71596 | M38: VIA TURBIGACCIO, SN | N38: Lonate Pozzolo | O38: Duereti terminali compresi | P38: CHIUSO | S38: DU10-4-141308 | T38: NODO RIGIDO | U38: 45,552468- 8,7193 | V38: Nosate | W38: Definitivo | Z38: P | AA38: 800 | AD38: IT001E120946587 | AE38: DU30-2-524956 | AF38: E-D | AG38: E-D | AI38: SI | AK38: DU10.2.436909 - DU10.2.488047
A39: 36 | B39: Duereti | C39: CASTANO P. | D39: DU1021541 | E39: =VLOOKUP(D39,Foglio1!A36:B4161,2,FALSE) -> MALPAGA | G39: DU30-2-335962 | H39: ALZAIA NG | I39: VIA ALZAIA NAVIGLIO GRANDE | J39: Lonate Pozzolo | K39: DU30-2-335962 | L39: 45.564468 - 8.71677 | M39: VIA ALZAIA NAVIGLIO GRANDE | N39: Lonate Pozzolo | O39: Duereti terminali compresi | P39: CHIUSO | S39: DU10-4-314857 | T39: NODO RIGIDO | U39: 45,566813-8,718988 | V39: Nosate | W39: Definitivo | AD39: IT001E120946811 | AE39: DU30-2-335962 | AF39: E-D | AG39: E-D | AI39: Telecontrollabile | AK39: DU10.3.124508 - DU10.2.384576
A40: 37 | B40: Duereti | C40: CASTANO P. | D40: DU1021541 | E40: =VLOOKUP(D40,Foglio1!A37:B4162,2,FALSE) -> MALPAGA | G40: DU30-2-494471 | H40: S.SIRO | I40: VIA S.S. SIRO | J40: Lonate Pozzolo | K40: DU30-2-494471 | L40: 45.573018 - 8.718887 | M40: VIA S.S. SIRO | N40: Lonate Pozzolo | O40: Duereti terminali compresi | P40: APERTO | S40: DU10-3-124508 | T40: SEZ.A PALO | U40: 45,570679 - 8,719189 | V40: Nosate | W40: Definitivo | X40: S | Y40: 1300 | Z40: S | AA40: 1850 | AD40: IT001E120948156 | AE40: DU30-2-494471 | AF40: E-D | AG40: E-D | AI40: Telecontrollabile | AK40: DU10.3.124508 - DU10.2.384576
...

Sheet Foglio1
A5: CODE_SG | B5: NOME
A10: DU1024855 | B10: VIGEVANESE
B11: (sec)
B12: (ms)
A14: DU1034319 | B14: 1BORDONI
B15: (sec)
B16: (ms)
B17: (ms)
B18: (ms)
B19: (sec)
A23: DU1041509 | B23: 109MOLINET
B24: (sec)
B25: (ms)
B26: (ms)
B27: (ms)
B28: (sec)
A32: DU1030947 | B32: TRAVAGLIA
B33: (sec)
B34: (ms)
B35: (ms)
B36: (ms)
B37: (sec)
A41: P | B41: CERAMICA
B42: (sec)
B43: (ms)
B44: (ms)
B45: (ms)
B46: (sec)
A50: DU1028250 | B50: TESSERA
A51: DU1026569 | B51: BUCCINASCO
B52: (sec)
B53: (ms)
A55: DU1029855 | B55: ZIF
B56: (sec)
B57: (ms)
B58: (ms)
B59: (ms)
B60: (sec)
A64: DU1037645 | B64: ASSAGO
B65: (sec)
...

Sheet BT
A1: ID Regolam. Esercizio | C1: Caratteristiche Tecniche Punto di Interconnessione BT | P1: Caratteristiche del Punto di Misura | U1: Zona di competenza | W1: Note
L2: Da E-distribuzione a Duereti | N2: Da Duereti a E-distribuzione
B3: Distributore alimentante | C3: Cabina secondaria (o nodo) alimentante | D3: Numero di partenza BT | E3: Denominazione e/o indirizzo della cabina (nodo) | F3: Comune della cabina | G3: Ubicazione del punto di confine | H3: Indirizzo | I3: Comune | J3: Coordinate geografiche del punto di confine | K3: Utenze alimentate | L3: Condizione standard di esercizio | M3: potenza disponibile kW | N3: Condizione standard di esercizio | O3: potenza disponibile kW | P3: POD ED | Q3: POD Duereti | R3: Ubicazione del misuratore | S3: Proprietà misuratore | T3: Proprietà Riduttori | U3: Duereti | V3: E-distribuzione | W3: (Somma dei clienti)
A4: 1 | B4: E-distribuzione | C4: 102090 | D4: A | E4: PE-CASELLO TEEM - S.P. 13 | F4: Caponago | G4: Morsetti superiori interruttore BT di separazione | H4: S.P. 13 | I4: CAPONAGO | J4: 45,559051 - 9,388968 | K4: Utenze BT in Via Galilei | L4: C | M4: 100 | P4: IT001E12412099 | R4: Presso CS 102090 PE-CASELLO TEEM | S4: E-distribuzione | T4: E-distribuzione | V4: LOM-UT MB -BLUE TEAM VIMERCATE
A5: 2 | B5: E-distribuzione | C5: 118303 | D5: B | E5: posso | F5: Rivolta d'Adda | G5: Morsetti superiori interruttore BT di separazione | H5: C.na Colomba | I5: RIVOLTA D'ADDA | J5: 45,497385 - 9,511009 | K5: Utenze BT in Via Bosco Verdi | L5: C | M5: 30 | P5: IT001E12441973 | R5: Presso interruttore in cassetto stradale adiacente CS118303 | S5: E-distribuzione | T5: E-distribuzione | V5: LOM-UT CR-LO -BLUE TEAM CREMONA
A6: 3 | B6: Duereti | C6: 120260 | D6: B | E6: VIA SICILIA - V.SICILIA | F6: Magnago | G6: Morsetti inferiori misuratore di scambio BT | H6: Via Delle Brugherie | I6: MAGNAGO | J6: 45,575200 - 8,835319 | K6: Utenze BT in Via Bienate | N6: C | O6: 40 | P6: IT001E12418826 | R6: Presso locale contatori cliente | S6: Duereti | T6: Duereti | V6: LOM-UT VA -BLUE TEAM BUSTO ARSIZIO
A7: 4 | B7: E-distribuzione | C7: 121316 | D7: A | E7: CAIELLA - STR.CASORATE-MOTTA | F7: Casorate Primo | G7: Morsetti superiori dei misuratori dei clienti con POD: IT001E14905566 IT001E18163131 | H7: Via Cavour | I7: MOTTA VISCONTI | J7: Coordinate dei POD Clienti | K7: Utenze BT in Via Cavour | L7: C | M7: 20 | P7: IT001E12436928 | R7: Misura dell'energia mediante misuratori clienti | S7: E-distribuzione | T7: E-distribuzione | V7: LOM-UT PV -BLUE TEAM PAVIA
A8: 5 | B8: E-distribuzione | C8: 121607 | D8: A | E8: CHIMICA - MOLINO MOLGORA COMAZZO | F8: Comazzo | G8: Morsetti superiori interruttore BT di separazione | H8: Via Mulino / STR PR 181 | I8: COMAZZO | J8: 45,468144 - 9,443876 | K8: Utenze BT in Via Mulino | L8: C | M8: 20 | P8: IT001E12456263 | R8: Presso interruttore in cassonetto stradale ai piedi del palo | S8: E-distribuzione | T8: E-distribuzione | V8: LOM-UT CR-LO -BLUE TEAM LODI
A9: 6 | B9: Duereti | C9: 129977 | D9: A | E9: PE-ITALINOX - VIA ALZAIA | F9: Pessano con Bornago | G9: Morsetti superiori interruttore BT di separazione | H9: SP13 | I9: PESSANO | J9: 45,557111 - 9,383596 | K9: Utenze BT in Via Caponago Pessano | N9: C | O9: 30 | P9: IT001E12314729 | R9: Presso interruttore in cassonetto su palo | S9: Duereti | T9: Duereti | V9: LOM-UT MB -BLUE TEAM VIMERCATE
A10: 7 | B10: Duereti | C10: 135955 | D10: B | E10: DEPURATORE - CASCINA MALINGAMBA | F10: Lainate | G10: Morsetti inferiori misuratore di scambio BT | H10: Via per Lainate | I10: LAINATE | J10: 45,585158 - 9,024696 | K10: Utenze BT in Via Lainate | N10: C | O10: 110 | P10: IT001E12418846 | R10: Presso cassonetto su palo | S10: Duereti | T10: Duereti | V10: LOM-UT VA -BLUE TEAM SARONNO
A11: 8 | B11: E-distribuzione | C11: 143176 | D11: A | E11: DELL'ACQUA - STR.PER BESATE | F11: Casorate Primo | G11: Morsetti superiori dei misuratori dei clienti con POD: IT001E11104075 IT001E16637268 | H11: Via Novellino | I11: BUBBIANO | J11: Coordinate dei POD Clienti | K11: Utenze BT in Via Novellino | L11: C | M11: 20 | P11: IT001E12436951 | R11: Misura dell'energia mediante misuratori clienti | S11: E-distribuzione | T11: E-distribuzione | V11: LOM-UT PV -BLUE TEAM PAVIA
A12: 9 | B12: E-distribuzione | C12: 146487 | D12: A | E12: V.SAN CARLO - VIA S.CARLO 6 | F12: Cologno Monzese | G12: Morsetti superiori dei misuratori dei clienti con POD: IT001E14509823 | H12: Via San Carlo | I12: VIMODRONE | J12: Coordinate dei POD Clienti | K12: Utenze BT in Via San Carlo | L12: C | M12: 90 | P12: IT001E12500097 | R12: Misura dell'energia mediante misuratori clienti | S12: E-distribuzione | T12: E-distribuzione | V12: LOM-UT MB -BLUE TEAM MONZA
A13: 10 | B13: E-distribuzione | C13: 146487 | D13: D | E13: V.SAN CARLO - VIA S.CARLO 6 | F13: Cologno Monzese | G13: Morsetti superiori dei misuratori dei clienti con POD: IT001E17612846 | H13: Via San Carlo | I13: VIMODRONE | J13: Coordinate dei POD Clienti | K13: Utenze BT in Via San Carlo | L13: C | M13: 90 | P13: IT001E12500241 | R13: Misura dell'energia mediante misuratori clienti | S13: E-distribuzione | T13: E-distribuzione | V13: LOM-UT MB -BLUE TEAM MONZA
A14: 11 | B14: Duereti | C14: 160166 | D14: D | E14: Q.RE OLONA - V.CANOVA, 73 | F14: Legnano | G14: Morsetti superiori dei misuratori dei clienti con POD: | H14: Via Adige | I14: CASTELLANZA | J14: Coordinate dei POD Clienti | K14: Utenze BT in Via Adige | N14: C | O14: 10 | P14: IT001E12418862 | R14: Misura dell'energia mediante misuratori clienti | S14: Duereti | T14: Duereti | V14: LOM-UT VA -BLUE TEAM SARONNO
A15: 12 | B15: Duereti | C15: 160166 | D15: D | E15: Q.RE OLONA - V.CANOVA, 73 | F15: Legnano | G15: Morsetti inferiori misuratore di scambio BT | H15: Via Antonio Canova | I15: LEGNANO | J15: 45,607245 - 8,913903 | K15: Utenze BT in Via Locatelli | N15: C | O15: 50 | P15: IT001E12418871 | R15: Presso cassonetto su palo | S15: Duereti | T15: Duereti | V15: LOM-UT VA -BLUE TEAM SARONNO
A16: 13 | B16: E-distribuzione | C16: 162896 | D16: A | E16: S.C.PETROLI - VIA CERRO | F16: Uboldo | G16: Morsetti superiori dei misuratori dei clienti con POD: IT001E17612846 | H16: Via Resegone | I16: CERRO MAGGIORE | J16: Coordinate dei POD Clienti | K16: Utenze BT in Via Resegone | L16: C | M16: 10 | P16: IT001E12436964 | R16: Misura dell'energia mediante misuratori clienti | S16: E-distribuzione | T16: E-distribuzione | V16: LOM-UT VA -BLUE TEAM SARONNO
A17: 14 | B17: E-distribuzione | C17: 167948 | D17: 7 | E17: RODIO - S.P. PANDINA | F17: Casalmaiocco | G17: Morsetti superiori dei misuratori dei clienti con POD: IT001E15492418 IT001E15492715 IT001E15492463 IT001E18273144 IT001E15492412 IT001E15492459 IT001E15210053 IT001E15492408 IT001E18307994 IT001E15492427 IT001E15492464 IT001E15492409 IT001E15492405 IT001E15492457 IT001E15210051 IT001E15492410 IT001E15492406 IT001E15492472 IT001E15492454 IT001E15492414 IT001E15492437 IT001E15492455 IT001E15492456 IT001E15492458 IT001E15492436 IT001E15492719 IT001E15492462 IT001E15492465 IT001E15210052 IT001E15492451 IT001E15492721 IT001E15492460 IT001E15492469 IT001E15492722 IT001E15492468 IT001E15492438 IT001E15492411 IT001E15492452 IT001E15492426 IT001E15492413 IT001E15492720 IT001E15492415 IT001E15492450 IT001E15492718 IT001E15492407 IT001E15492466 IT001E15492416 IT001E15492453 IT001E15492435 IT001E15492291 IT001E15492467 IT001E16641608 IT001E15492434 IT001E15492716 IT001E16557012 IT001E14196460 IT001E15492447 IT001E15492431 IT001E04420366 IT001E14196458 IT001E15492430 IT001E15492439 IT001E15492395 IT001E15492377 IT001E16557019 IT001E15492389 IT001E15492486 IT001E15492397 IT001E15492441 IT001E15492384 IT001E15492404 IT001E16557011 IT001E15492380 IT001E15492379 IT001E15492394 IT001E15492449 IT001E15492491 IT001E15492385 IT001E15492445 IT001E15492489 IT001E16557014 IT001E15492381 IT001E15492440 IT001E15492383 IT001E15492429 IT001E15492471 IT001E15492386 IT001E15492425 IT001E16557016 IT001E15492388 IT001E15492433 IT001E15492428 IT001E15492461 IT001E15492378 IT001E15492448 IT001E15492432 IT001E16557013 IT001E15492391 IT001E15492442 IT001E15492387 IT001E15492487 IT001E15492473 IT001E15492474 IT001E14010935 IT001E16557010 IT001E15492488 IT001E15492470 IT001E15492443 IT001E15492710 IT001E15492382 IT001E15492390 IT001E16557017 IT001E15492717 IT001E15492392 IT001E15492393 IT001E15492446 IT001E15492396 IT001E16557018 IT001E15492444 IT001E14173946 IT001E16557015 IT001E16557009 | H17: Via Brescia/Via Novara/Via Melegnano | I17: DRESANO | J17: Coordinate dei POD Clienti | K17: Utenze BT in Via Brescia/Via Novara/Via Melegnano | L17: C | M17: 290 | P17: IT001E12436594 | R17: Misura dell'energia mediante misuratori clienti | S17: E-distribuzione | T17: E-distribuzione | V17: LOM-UT CR-LO -BLUE TEAM LODI
A18: 15 | B18: Duereti | C18: 168174 | D18: A | E18: CHIERICHETTI - V.SARDEGNA | F18: Magnago | G18: Morsetti superiori dei misuratori dei clienti con POD: | H18: Via Novara | I18: BUSTO ARSIZIO | J18: Coordinate dei POD Clienti | K18: Utenze BT in Via Novara | N18: C | O18: 70 | P18: IT001E12499169 | R18: Misura dell'energia mediante misuratori clienti | S18: Duereti | T18: Duereti | V18: LOM-UT VA -BLUE TEAM BUSTO ARSIZIO
A19: 16 | B19: E-distribuzione | C19: 178901 | D19: B | E19: V.BINDA - VIA BINDA, 21 | F19: Castellanza | G19: Morsetti superiori dei misuratori dei clienti con POD: IT001E17517382 IT001E17517381 IT001E17517385 IT001E17517386 IT001E17517391 IT001E16543701 IT001E17517392 IT001E17517379 IT001E17517387 IT001E17517389 IT001E17517388 IT001E17410286 IT001E17517383 IT001E17517390 IT001E17517384 IT001E17517380 IT001E04308421 | H19: Via Castellanza 47-104 | I19: LEGNANO | J19: Coordinate dei POD Clienti | K19: Utenze BT in Via Castellanza 47-104 | L19: C | M19: 100 | P19: IT001E12500082 | R19: Misura dell'energia mediante misuratori clienti | S19: E-distribuzione | T19: E-distribuzione | V19: LOM-UT VA -BLUE TEAM SARONNO
A20: 17 | B20: Duereti | C20: 184096 | D20: E | E20: CU-V.PONCHIELLI - VIA PONCHIELLI 2 | F20: Cernusco sul Naviglio | G20: Morsetti inferiori misuratore di scambio BT | H20: Via Ponchielli | I20: CERNUSCO | J20: 45,541037 - 9,338295 | K20: Utenze BT in Via Don Surzio | N20: C | O20: 30 | P20: IT001E12418482 | R20: Presso CS 184096 | S20: Duereti | T20: Duereti | V20: LOM-UT MB -BLUE TEAM VIMERCATE
A21: 18 | B21: Duereti | C21: 189376 | D21: A | E21: CS-C.TARANTA - C.NA TARANTA | F21: Cassano d'Adda | G21: Morsetti superiori dei misuratori dei clienti con POD: IT001E14283694 IT001E28579747 | H21: Via Venezia, 80 | I21: FARA GERA D'ADDA | J21: 45,525446 - 9,539051 | K21: Utenze BT in Via Venezia | N21: C | O21: 10 | P21: IT001E12499187 | R21: Misura dell'energia mediante misuratori clienti | S21: Duereti | T21: Duereti | V21: LOM-UT BG -BLUE TEAM TREVIGLIO
A22: 19 | B22: E-distribuzione | C22: 197973 | D22: B | E22: V.MILANO - VIA MILANO (OPP.161) | F22: Cologno Monzese | G22: Morsetti superiori dei misuratori dei clienti con POD: IT001E14275675 IT001E17204510 IT001E17680090 IT001E15400431 | H22: Via Santa Rita | I22: VIMODRONE | J22: Coordinate dei POD Clienti | K22: Utenze BT in Via Santa Rita | L22: C | M22: 10 | P22: IT001E12436986 | R22: Misura dell'energia mediante misuratori clienti | S22: E-distribuzione | T22: E-distribuzione | V22: LOM-UT MB -BLUE TEAM MONZA
A23: 20 | B23: Duereti | C23: 222396 | D23: D | E23: POGGIO - V.XXIV MAGGIO, 229 | F23: Legnano | G23: Morsetti inferiori misuratore di scambio BT | H23: Via Dandolo | I23: CASTELLANZA | J23: 45,607469 - 8,903889 | K23: Utenze BT in Via Dandolo | N23: C | O23: 120 | P23: IT001E12179528 | R23: Presso cassonetto stradale vicino al nodo di sezionamento 5.193037 | S23: Duereti | T23: Duereti | V23: LOM-UT VA -BLUE TEAM SARONNO
A24: 21 | B24: E-distribuzione | C24: 227568 | D24: A | E24: MAYER - VIA V GIORNATE, 2045 | F24: Caronno Pertusella | G24: Morsetti superiori interruttore BT di separazione | H24: Viale Cinque Giornate (S.P. 233), 121 | I24: CARONNO PERTUSELLA | J24: 45,581352 - 9,060561 | K24: Utenze BT in Via Pelloritana | L24: C | M24: 40 | P24: IT001E12436995 | R24: Presso interruttore in cassonetto stradale su aiuola distributore Q8 | S24: E-distribuzione | T24: E-distribuzione | V24: LOM-UT VA -BLUE TEAM SARONNO
A25: 22 | B25: E-distribuzione | C25: 234990 | D25: 2 | E25: ST.SERVIZIO - S.S. 412 VALTIDONE | F25: Landriano | G25: Morsetti superiori dei misuratori dei clienti con POD: IT001E15497201 | H25: Via Longora | I25: CARPIANO | J25: Coordinate dei POD Clienti | K25: Utenze BT in Via Longora | L25: C | M25: 50 | P25: IT001E12437002 | R25: Misura dell'energia mediante misuratori clienti | S25: E-distribuzione | T25: E-distribuzione | V25: LOM-UT PV -BLUE TEAM PAVIA
A26: 23 | B26: E-distribuzione | C26: 246815 | D26: A | E26: FE28 BIS - VIA CASSINO D'ALBERI SN | F26: Mulazzano | G26: Morsetti superiori interruttore BT di separazione | H26: Loc. Cimitero | I26: MULAZZANO | J26: 45,398601 - 9,388723 | K26: Utenze BT in Via Villambrera | L26: C | M26: 10 | P26: IT001E12442039 | R26: Nel locale contatori della cs 246815 - FE28 BIS | S26: E-distribuzione | T26: E-distribuzione | V26: LOM-UT CR-LO -BLUE TEAM LODI
A27: 24 | B27: Duereti | C27: 255038 | D27: C | E27: CS-CEPAV 2 - C.NA CESARINA verso Treviglio Via Del Bosco | F27: Cassano d'Adda | G27: Morsetti superiori interruttore BT di separazione | H27: Via Del Bosco | I27: CASSANO D'ADDA | J27: 45,51174 - 9,547859 | K27: Utenze BT in Via Del Bosco / Via Broli | N27: C | O27: 60 | P27: IT001E12397004 | R27: Presso interruttore in cassonetto stradale adiacente a CS 255038 CEPAV2 | S27: Duereti | T27: Duereti | V27: LOM-UT BG -BLUE TEAM TREVIGLIO
A28: 25 | B28: Duereti | C28: 257854 | D28: A | E28: MA-C.GRANDI - VIA A.GRANDI SN | F28: Masate | G28: Morsetti superiori interruttore BT di separazione | H28: SP179 - Discarica | I28: MASATE | J28: 45,568136 - 9,470680 | K28: Utenze BT in Via del Vialone | N28: C | O28: 10 | P28: IT001E12314751 | R28: Presso interruttore in cassonetto su palo | S28: Duereti | T28: Duereti | V28: LOM-UT MB -BLUE TEAM VIMERCATE
A29: 26 | B29: E-distribuzione | C29: 271133 | D29: A | E29: NUOVA CASORATE - VIA DEI PINI 1 | F29: Casorate Primo | G29: Morsetti superiori dei misuratori dei clienti con POD: IT001E14929741 IT001E14022113 IT001E14929739 IT001E18537151 IT001E14929740 IT001E14013610 IT001E15010031 IT001E14022112 | H29: Via Roboni | I29: VERNATE | J29: Coordinate dei POD Clienti | K29: Utenze BT in Via Roboni | L29: C | M29: 50 | P29: IT001E12436608 | R29: Misura dell'energia mediante misuratori clienti | S29: E-distribuzione | T29: E-distribuzione | V29: LOM-UT PV -BLUE TEAM PAVIA
A30: 27 | B30: E-distribuzione | C30: 282081 | D30: 1 | E30: MADONNINA - VIA VERONA 3 | F30: Casalmaiocco | G30: Morsetti superiori dei misuratori dei clienti con POD: IT001E15492284 IT001E04872911 IT001E15492274 IT001E15492272 IT001E15492273 IT001E14258409 IT001E15492357 IT001E15492281 IT001E15492279 IT001E15492275 IT001E15492280 IT001E15492265 IT001E15492270 IT001E15318365 IT001E15492278 IT001E15492277 IT001E15492365 IT001E15492267 IT001E15492282 IT001E15492355 IT001E15492360 IT001E15492264 IT001E15492266 IT001E15492358 IT001E15492285 IT001E15492367 IT001E15492286 IT001E15492263 IT001E15492276 IT001E15492271 IT001E15492283 IT001E15492363 IT001E15492356 IT001E15492359 IT001E15492362 IT001E15492287 IT001E15492366 IT001E15492269 IT001E15492361 IT001E15492268 IT001E15492364 IT001E15492288 IT001E15492292 IT001E15492289 IT001E17266548 IT001E15492290 | H30: Via Verona/Via Mantova | I30: DRESANO | J30: Coordinate dei POD Clienti | K30: Utenze BT in Via Verona/Via Mantova | L30: C | M30: 110 | P30: IT001E12436615 | R30: Misura dell'energia mediante misuratori clienti | S30: E-distribuzione | T30: E-distribuzione | V30: LOM-UT CR-LO -BLUE TEAM LODI
A31: 28 | B31: E-distribuzione | C31: 282081 | D31: 3 | E31: MADONNINA - VIA VERONA 3 | F31: Casalmaiocco | G31: Morsetti superiori dei misuratori dei clienti con POD: IT001E15492242 IT001E15492422 IT001E15492295 IT001E15492304 IT001E16044561 IT001E17651686 IT001E15492300 IT001E15492240 IT001E04649531 IT001E15492296 IT001E15492297 IT001E15492310 IT001E15492302 IT001E15492714 IT001E15492303 IT001E15492351 IT001E15492234 IT001E15492293 IT001E14546139 IT001E15333103 IT001E15316283 IT001E15321288 IT001E15492711 IT001E17651679 IT001E15315614 IT001E17651684 IT001E17712349 IT001E17666312 IT001E17651678 IT001E15492239 IT001E15092344 IT001E14313143 IT001E17651680 IT001E15492241 IT001E15492308 IT001E15492299 IT001E15492305 IT001E15492243 IT001E15492319 IT001E15492313 IT001E15492307 IT001E15492231 IT001E15492337 IT001E15492306 IT001E15492333 IT001E18293061 IT001E15492322 IT001E15492332 IT001E15492235 IT001E15492334 IT001E15011461 IT001E15492316 IT001E14705701 IT001E15492236 IT001E15492338 IT001E15492245 IT001E17651681 IT001E15492311 IT001E15492238 IT001E15492352 IT001E15492294 IT001E15492246 IT001E15492312 IT001E17651687 IT001E15314874 IT001E15492350 IT001E15492233 IT001E15492232 IT001E15492237 IT001E17651685 IT001E15492244 IT001E17651683 IT001E15492321 IT001E18191084 IT001E15492419 IT001E15492326 IT001E15492402 IT001E15492315 IT001E15492424 IT001E15492301 IT001E15492309 IT001E15492314 IT001E15492423 IT001E17651682 IT001E15091907 IT001E15492335 IT001E15492421 IT001E15492252 IT001E15492401 IT001E15492258 IT001E15492262 IT001E14313144 IT001E15576892 IT001E15492248 IT001E15492398 IT001E15492403 IT001E15492347 IT001E15492254 IT001E15492348 IT001E04113696 IT001E15492336 IT001E15492253 IT001E15492399 IT001E15492256 IT001E18113182 IT001E15492325 IT001E15492255 IT001E15492251 IT001E15492372 IT001E15492320 IT001E15492331 IT001E18115194 IT001E15492370 IT001E15492329 IT001E15492354 IT001E15492318 IT001E15492257 IT001E15492259 IT001E15326404 IT001E15492324 IT001E15492261 IT001E15492349 IT001E15492371 IT001E15492400 IT001E15492323 IT001E18113184 IT001E15492340 IT001E15492375 IT001E15492250 IT001E15492341 IT001E15492298 IT001E18185878 IT001E15492373 IT001E14207613 IT001E15492328 IT001E18113183 IT001E15492344 IT001E15492330 IT001E15492374 IT001E15492346 IT001E15492343 IT001E15492339 IT001E15492247 IT001E15492249 IT001E15492260 IT001E15492345 IT001E14510945 IT001E15492342 | H31: Via Mantova/Via Piacenza/Via Genova | I31: DRESANO | J31: Coordinate dei POD Clienti | K31: Utenze BT in Via Mantova/Via Piacenza/Via Genova | L31: C | M31: 300 | P31: IT001E12436626 | R31: Misura dell'energia mediante misuratori clienti | S31: E-distribuzione | T31: E-distribuzione | V31: LOM-UT CR-LO -BLUE TEAM LODI
A32: 29 | B32: E-distribuzione | C32: 284719 | D32: A | E32: VIA MAZZINI - VIA MAZZINI | F32: Sordio | G32: Morsetti superiori dei misuratori dei clienti con POD: IT001E15315607 | H32: Villa Bissone | I32: SAN ZANONE AL LAMBRO | J32: Coordinate dei POD Clienti | K32: Utenze BT in Villa Bissone | L32: C | M32: 10 | P32: IT001E12510681 | R32: Misura dell'energia mediante misuratori clienti | S32: E-distribuzione | T32: E-distribuzione | V32: LOM-UT CR-LO -BLUE TEAM LODI
A33: 30 | B33: E-distribuzione | C33: 300270 | D33: A | E33: ERFROG - VIA ASTI | F33: Cologno Monzese | G33: Morsetti superiori dei misuratori dei clienti con POD: IT001E15393433 IT001E15393431 IT001E15393432 IT001E15393369 IT001E15393429 | H33: Via Metallino | I33: VIMODRONE | J33: Coordinate dei POD Clienti | K33: Utenze BT in Via Metallino | L33: C | M33: 230 | P33: IT001E12424549 | R33: Misura dell'energia mediante misuratori clienti | S33: E-distribuzione | T33: E-distribuzione | V33: LOM-UT MB -BLUE TEAM MONZA
A34: 31 | B34: Duereti | C34: 304154 | D34: B | E34: MASSERECCIO - V.MASSARECCIO | F34: Legnano | G34: Morsetti inferiori misuratore di scambio BT | H34: Via Gerenzano | I34: LEGNANO | J34: 45,619855 - 8,927073 | K34: Utenze BT in Via Gerenzano | N34: C | O34: 10 | P34: IT001E12418882 | R34: Presso interruttore su cassonetto stradale | S34: Duereti | T34: Duereti | V34: LOM-UT VA -BLUE TEAM SARONNO
A35: 32 | B35: E-distribuzione | C35: 340381 | D35: A | E35: CR-V.PO - VIA PO SN | F35: Carugate | G35: Morsetti superiori dei misuratori dei clienti con POD: IT001E14684587 IT001E16014769 IT001E15764130 IT001E15868575 | H35: Via Monza | I35: BUSSERO | J35: Coordinate dei POD Clienti | K35: Utenze BT in Via Monza | L35: C | M35: 10 | P35: IT001E12424422 | R35: Misura dell'energia mediante misuratori clienti | S35: E-distribuzione | T35: E-distribuzione | V35: LOM-UT MB -BLUE TEAM VIMERCATE
A36: 33 | B36: E-distribuzione | C36: 340381 | D36: C | E36: CR-V.PO - VIA PO SN | F36: Carugate | G36: Morsetti superiori dei misuratori dei clienti con POD: IT001E15752524 IT001E14755012 | H36: Via Monza | I36: BUSSERO | J36: Coordinate dei POD Clienti | K36: Utenze BT in Via Monza | L36: C | M36: 10 | P36: IT001E12437008 | R36: Misura dell'energia mediante misuratori clienti | S36: E-distribuzione | T36: E-distribuzione | V36: LOM-UT MB -BLUE TEAM VIMERCATE
A37: 34 | B37: Duereti | C37: 345761 | D37: 3 | E37: VILLABISSONE - VIA EMILIA | F37: San Zenone al Lambro | G37: Morsetti superiori dei misuratori dei clienti con POD: | H37: Via Case Cambié | I37: SORDIO | J37: Coordinate dei POD Clienti | K37: Utenze BT in Via Case Cambié | N37: C | O37: 40 | P37: IT001E12499023 | R37: Misura dell'energia mediante misuratori clienti | S37: Duereti | T37: Duereti | V37: LOM-UT CR-LO -BLUE TEAM LODI
A38: 35 | B38: Duereti | C38: 345761 | D38: 4 | E38: VILLABISSONE - VIA EMILIA | F38: San Zenone al Lambro | G38: Morsetti superiori dei misuratori dei clienti con POD: | H38: Via Emilia | I38: SORDIO | J38: Coordinate dei POD Clienti | K38: Utenze BT in Via Emilia | N38: C | O38: 70 | P38: IT001E12498802 | R38: Misura dell'energia mediante misuratori clienti | S38: Duereti | T38: Duereti | V38: LOM-UT CR-LO -BLUE TEAM LODI
A39: 36 | B39: Duereti | C39: 359818 | D39: B | E39: VIVALDI - V.VIVALDI, 17 | F39: Legnano | G39: Morsetti inferiori misuratore di scambio BT | H39: Via Beethoven | I39: LEGNANO | J39: 45,611917 - 8,922368 | K39: Utenze BT in Via Massereccio | N39: C | O39: 80 | P39: IT001E12418886 | R39: Presso interruttore su cassonetto stradale adiacente nodo BT 6.189920 | S39: Duereti | T39: Duereti | V39: LOM-UT VA -BLUE TEAM SARONNO
A40: 37 | B40: E-distribuzione | C40: 363631 | D40: B | E40: EN.FERRARIO - VIA VERDI, SN - CARONNO P. | F40: Caronno Pertusella | G40: Morsetti superiori interruttore BT di separazione | H40: Via Niccolò Paganini, 143 | I40: CARONNO PERTUSELLA | J40: 45,580859 - 9,053856 | K40: Utenze BT in Via Piemonte / Via Broccana | L40: C | M40: 10 | P40: IT001E12437021 | R40: Presso interruttore in cassonetto stradale adiacente al civ 143 | S40: E-distribuzione | T40: E-distribuzione | V40: LOM-UT VA -BLUE TEAM SARONNO
...
